<?xml version="1.0" encoding="utf-8"?>

<robot
  name="robot">

  <gazebo>
        <plugin name="gazebo_ros_control" filename="libgazebo_ros_control.so">
            <robotNamespace>/robot</robotNamespace>
        </plugin>
  </gazebo>

  <link name="World"/>

  <joint name="fixeIt" type="fixed">
        <parent link="World" />
        <child link="Chassis"/>
  </joint>

  <link
    name="Chassis">
    <inertial>
      <origin
        xyz="0.00014205 0.10102 0.35349"
        rpy="0 0 0" />
      <mass
        value="0.1" />
      <inertia
        ixx="0.25171"
        ixy="0.00012432"
        ixz="2.1175E-06"
        iyy="0.16354"
        iyz="-0.0051414"
        izz="0.21853" />
    </inertial>
    <visual>
      <origin
        xyz="0 0 0"
        rpy="0 0 0" />
      <geometry>
        <mesh
          filename="package://robot/meshes/Chassis.STL" />
      </geometry>
      <material
        name="red">
        <color
          rgba="0.79216 0.81961 0.93333 1" />
      </material>
    </visual>
    <collision>
      <origin
        xyz="0 0 0"
        rpy="0 0 0" />
      <geometry>
        <mesh
          filename="package://robot/meshes/Chassis.STL" />
      </geometry>
    </collision>
  </link>

   <gazebo reference="Chassis">
        <kp>1000.0</kp>
        <kd>1000.0</kd>
        <mu1>0</mu1>
        <mu2>0</mu2>
  </gazebo>
  
  <link
    name="LeftWheel">
    <inertial>
      <origin
        xyz="1.3878E-17 -7.6328E-17 -0.025"
        rpy="0 0 0" />
      <mass
        value="0.02" />
      <inertia
        ixx="0.0081854"
        ixy="2.1684E-19"
        ixz="2.4283E-18"
        iyy="0.0081854"
        iyz="2.143E-18"
        izz="0.015455" />
    </inertial>
    <visual>
      <origin
        xyz="0 0 0"
        rpy="0 0 0" />
      <geometry>
        <mesh
          filename="package://robot/meshes/LeftWheel.STL" />
      </geometry>
      <material
        name="blue">
        <color
          rgba="0.79216 0.81961 0.93333 1" />
      </material>
    </visual>
    <collision>
      <origin
        xyz="0 0 0"
        rpy="0 0 0" />
      <geometry>
        <mesh
          filename="package://robot/meshes/LeftWheel.STL" />
      </geometry>
    </collision>
  </link>

  <gazebo reference="LeftWheel">
        <kp>1000.0</kp>
        <kd>1000.0</kd>
        <mu1>0</mu1>
        <mu2>0</mu2>
  </gazebo>

  <joint
    name="LeftDrive"
    type="continuous">
    <parent
      link="Chassis" />
    <child
      link="LeftWheel" />
    <origin
      xyz="0.32409 0 0.11844"
      rpy="-1.5708 1.3382 1.5708" />
    <axis
      xyz="0 0 1" />
    <limit
      lower="1"
      upper="-1"
      effort="1"
      velocity="5" />
  </joint>

  <link
    name="RightWheel">
    <inertial>
      <origin
        xyz="7.8856E-17 1.3878E-17 -0.025"
        rpy="0 0 0" />
      <mass
        value="0.02" />
      <inertia
        ixx="0.0081854"
        ixy="3.3697E-34"
        ixz="-1.3457E-18"
        iyy="0.0081854"
        iyz="-1.7717E-18"
        izz="0.015455" />
    </inertial>
    <visual>
      <origin
        xyz="0 0 0"
        rpy="0 0 0" />
      <geometry>
        <mesh
          filename="package://robot/meshes/RightWheel.STL" />
      </geometry>
      <material
        name="blue">
        <color
          rgba="0.79216 0.81961 0.93333 1" />
      </material>
    </visual>
    <collision>
      <origin
        xyz="0 0 0"
        rpy="0 0 0" />
      <geometry>
        <mesh
          filename="package://robot/meshes/RightWheel.STL" />
      </geometry>
    </collision>
  </link>

  <gazebo reference="RightWheel">
        <kp>1000.0</kp>
        <kd>1000.0</kd>
        <mu1>0</mu1>
        <mu2>0</mu2>
  </gazebo>


  <joint
    name="RightDrive"
    type="continuous">
    <origin
      xyz="-0.32409 0 0.11844"
      rpy="1.5708 0 1.5708" />
    <parent
      link="Chassis" />
    <child
      link="RightWheel" />
    <axis
      xyz="0 0 -1" />
    <limit
      lower="1"
      upper="-1"
      effort="1"
      velocity="5" />
  </joint>

    <transmission name="left_wheel_trans">
      <type>transmission_interface/SimpleTransmission</type>
      <joint name="LeftDrive">
        <hardwareInterface>hardware_interface/EffortJointInterface</hardwareInterface>
      </joint>
      <actuator name="leftMotor">
        <hardwareInterface>hardware_interface/EffortJointInterface</hardwareInterface>
        <mechanicalReduction>1</mechanicalReduction>
      </actuator>
    </transmission>

     <transmission name="right_wheel_trans">
      <type>transmission_interface/SimpleTransmission</type>
      <joint name="RightDrive">
        <hardwareInterface>hardware_interface/EffortJointInterface</hardwareInterface>
      </joint>
      <actuator name="rightMotor">
        <hardwareInterface>hardware_interface/EffortJointInterface</hardwareInterface>
        <mechanicalReduction>1</mechanicalReduction>
      </actuator>
    </transmission>

</robot>
